Workbook
Name FAC_COST: Data_Analysis!$Y$74:$Y$85
Name FAC_DES: Data_Analysis!$X$74:$X$85
Name GEN_COST: Data_Analysis!$B$68:$B$85
Name GEN_DES: Data_Analysis!$A$68:$A$85
Name INVENTORY_LIST: '[1]Searchable Inventory Item List'!$B$5:$E$6314
Name NativeTimeline_DATE_OF_REQUEST1: #N/A
Name Slicer_ASSET_DESCRIPTION: #N/A
Name Slicer_LOCATION: #N/A
Name Slicer_VEHICLE_REG_NO.: #N/A
Name VEH_COST: Data_Analysis!$K$52:$K$96
Name VEH_DES: Data_Analysis!$J$52:$J$96

Sheet Vehicle
E5: VEHICLE REPAIR AND MAINTENANCE REGISTER - 2026
P7: ACTIONED BY | R7: DATE / COST | W7: REMARKS
C8: MONTH | D8: DATE OF REQUEST | E8: REQUESTOR | F8: MRSF No. | G8: NOTIFICATION STATUS | H8: REPAIR / MAINTENANCE LOCATION | I8: ASSET NO. | J8: VEHICLE REG NO. | K8: VEHICLE DESCRIPTION | L8: ODOMETER READING | M8: NEXT SERVICE MILEAGE | N8: DESCRIPTION OF REQUEST | O8: DESCRIPTION OF WORK DONE | P8: PARTS SUPPLIED BY | Q8: WORK DONE AT | R8: DATE TAKEN TO WORKSHOP | S8: STATUS OF WORK | T8: DATE COMPLETED | U8: DAYS TAKEN TO COMPLETE | V8: SPARES COST (NGN) | W8: JUSTIFICATION / EVALUATION

Sheet Equipment
E5: EQUIPMENT REPAIR AND MAINTENANCE REGISTER - 2026
P7: ACTIONED BY | R7: REMARKS
C8: MONTH | D8: DATE OF REQUEST | E8: REQUESTOR | F8: MRSF No. | G8: NOTIFICATION STATUS | H8: END USER | I8: LOCATION | J8: ASSET NO. | K8: ASSET DESCRIPTION | L8: DESCRIPTION OF REQUEST | M8: GENERATOR RUNNING HOURS | N8: NEXT SERVICE HOUR | O8: DESCRIPTION OF WORK DONE | P8: PARTS SUPPLIED BY | Q8: WORK DONE BY | R8: STATUS OF WORK | S8: DATE COMPLETED | T8: SPARES COST | U8: JUSTIFICATION / EVALUATION

Sheet Facility
E5: FACILITY REPAIR AND MAINTENANCE REGISTER - 2026
N7: ACTIONED BY | O7: REMARKS
C8: MONTH | D8: DATE OF REQUEST | E8: REQUESTOR | F8: MRSF No. | G8: NOTIFICATION STATUS | H8: END USER | I8: LOCATION | J8: ROOM / FLAT | K8: ASSET DESCRIPTION | L8: DESCRIPTION OF REQUEST | M8: DESCRIPTION OF WORK DONE | N8: NAME | O8: STATUS OF WORK | P8: SPARES COST (NGN)

Sheet Additions
B1: LOCATION DROP DOWN LIST
K2: EQUIPMENT JUSTIFICATION / EVALUATION | M2: VEHICLE JUSTIFICATION / EVALUATION
B3: EQUIPMENT | D3: VEHICLE | F3: FACILITY
B5: AK, LAGOS | D5: ABUJA | F5: AK, UYO | K5: Maintenance & Repair required to keep the equipment functional | M5: Reported faults or breakdown are resolved accordingly to ensure the vehicle performs optimally as required by the OEM
B6: DGS | D6: BONNY | F6: DGS | K6: 250 running hours service required as per OEM requirement | M6: Routine servicing required as per OEM expectation
B7: DR | D7: LAGOS | F7: DR
B8: GML | D8: PORT HARCOURT | F8: GML
B9: LAGOS OFFICE | D9: UYO | F9: LAGOS GUEST HOUSE
B10: PHC OFFICE | D10: WARRI | F10: LAGOS OFFICE
B11: TOMY | F11: PHC OFFICE
B12: CHAIRMAN, UYO | F12: TOMY RESIDENCE
B13: WOJI | F13: CHAIRMAN UYO
B14: AK, UYO | F14: WOJI
F15: AK GUEST HOUSE, LAGOS
F16: AK, LAGOS
H19: EQUIPMENT STATUS | I19: VEHICLE STATUS | J19: FACILITY STATUS
H21: Ongoing | I21: Ongoing | J21: Ongoing
H22: Pending | I22: Pending | J22: Pending
H23: Awaiting Spares | I23: Awaiting Spares | J23: Awaiting Spares
H24: Awaiting Funds | I24: Awaiting Funds | J24: Awaiting Funds
H25: Completed | I25: Completed | J25: Completed

Sheet List of Vehicles
B2: S/NO | D2: Asset Tag Number | E2: Reg No. | F2: Vehicle Make
B4: 1 | D4: 5550000190 | E4: PF 4079 SPY - PRADO | F4: PRADO
B5: 2 | D5: 5550000223 | E5: PHC 185 AM - NISSAN PICKUP | F5: NISSAN PICKUP
B6: 3 | D6: 5550000224 | E6: PHC 178 AM - NISSAN NAVARA | F6: NISSAN NAVARA
B7: 4 | D7: 5550000280 | E7: KRD 341 CE - PRADO | F7: PRADO
B8: 5 | D8: 5550000281 | E8: KRD 339 CE - PRADO | F8: PRADO
B9: 6 | D9: 5550000346 | E9: KRD 338 CE - PRADO | F9: PRADO
B10: 7 | D10: 5550000384 | E10: PHC 177 AM - TOYOTA PRADO | F10: TOYOTA PRADO
B11: 8 | D11: 5550000398 | E11: GGU 693 TX - TOYOTA HILUX | F11: TOYOTA HILUX
B12: 9 | D12: 5550000399 | E12: GGU 692 TX - TOYOTA HILUX | F12: TOYOTA HILUX
B13: 10 | D13: 5550000618 | E13: PHC 179 AM - TOYOTA HILUX | F13: TOYOTA HILUX
B14: 11 | D14: 5550000619 | E14: GGU 695 TX - TOYOTA HILUX | F14: TOYOTA HILUX
B15: 12 | D15: 5550000620 | E15: GGU 696 TX - TOYOTA HILUX | F15: TOYOTA HILUX
... B66: 63 | D66: 5550003637 | E66: SKN 317 AU - TOYOTA HIACE STANDARD ROOF AMBULANCE | F66: TOYOTA HIACE
B67: 64 | D67: PRIVATE (GML1) | E67: BDG 159 CL - TOYOTA CAMRY | F67: TOYOTA CAMRY
B68: 65 | D68: PRIVATE (AK1) | E68: AKD 407 BD - TOYOTA PRADO | F68: TOYOTA PRADO
B69: 66 | D69: PRIVATE (AK2) | E69: AJ 464 AJ - TOYOTA PRADO | F69: TOYOTA PRADO
B70: 67 | D70: PRIVATE (DGS) | E70: AAA 07 UB - RANGE ROVER | F70: RANGE ROVER
B71: 68 | D71: PRIVATE (GML2) | E71: FST 06 AZ - TOYOTA PRADO | F71: TOYOTA PRADO
B72: 69 | D72: PRIVATE (CHAIRMAN) | E72: AKD 490 SU - TOYOTA PRADO | F72: TOYOTA PRADO
B73: 70 | D73: PRIVATE (AK3) | E73: KSF 761 DV - LEXUS | F73: LEXUS
B74: 71 | D74: PRIVATE (DGS2) | E74: DE 51 CON - MERCEDES G-WAGON | F74: MERCEDES G-WAGON
B75: 72 | D75: PRIVATE (AK4) | E75: RBC 899 HN - TOYOTA HILUX | F75: TOYOTA HILUX
B76: 73 | D76: PRIVATE (AK5) | E76: EPE 520 CH - TOYOTA PRADO | F76: TOYOTA PRADO
B77: 74 | D77: PRIVATE (ANIEK U) | E77: AKD 380 EJ | F77: WRANGLER JEEP
B78: 75 | D78: PRIVATE (AK6) | E78: 47 | F78: BMW 6 SERIES
B79: 76 | D79: 27440 | E79: DBU 519 AA - TOYOTA HILUX | F79: TOYOTA HILUX
B80: 77 | D80: 27438 | E80: DBU 710 AA - TOYOTA HIACE BUS (DIESEL ENGINE) | F80: TOYOTA HIACE
B81: 78 | D81: FA000054 | E81: AFM 673 GL - TOYOTA FORTUNER | F81: TOYOTA FORTUNER
B82: 79 | D82: FA000059 | E82: AFM 301 GL -TOYOTA URBAN CRUISER | F82: TOYOTA URBAN CRUISER
B83: 80 | D83: FA000060 | E83: AFM 674 GL - TOYOTA URBAN CRUISER | F83: TOYOTA URBAN CRUISER
B84: 81 | D84: FA000055 | E84: AFM 302 GL - TOYOTA HIACE BUS (DIESEL ENGINE) | F84: TOYOTA HIACE
B85: 82 | D85: FA000056 | E85: AFM 304 GL - TOYOTA HILUX | F85: TOYOTA HILUX
B86: 83 | D86: FA000057 | E86: AFM 303 GL - TOYOTA HILUX | F86: TOYOTA HILUX
B87: 84 | D87: FA000058 | E87: AFM 675 GL - TOYOTA HILUX | F87: TOYOTA HILUX

Sheet List of Generators
B2: S/N | D2: Asset Tag Number | E2: Generator Details | F2: Location | G2: Custodian | P2: FACILITIES | R2: MONTH
B4: 1 | D4: 6660000017 | E4: WOJI YARD FG WILSON 40KVA GENERATOR | F4: Port Harcourt | G4: Woji Yard | P4: PHC OFFICE | R4: JAN
B5: 2 | D5: 6660000642 | E5: AK LAGOS 80KVA GENERATOR | F5: Lagos | G5: AK Residence | P5: DR | R5: FEB
B6: 3 | D6: 6660000794 | E6: DGS PERKINS 50KVA GENERATOR | F6: Port Harcourt | G6: DGS Residence | P6: DGS | R6: MAR
B7: 4 | D7: 6660000958 | E7: TOMY PERKINS 80KVA GENERATOR | F7: Lagos | G7: Tomy's Residence | P7: GML | R7: APR
B8: 5 | D8: 6660000959 | E8: TOMY PERKINS 40KVA GENERATOR | F8: Lagos | G8: Tomy's Residence | P8: DMD RESIDENCE | R8: MAY
B9: 6 | D9: 6660001338 | E9: LAGOS OFFICE PERKINS 100KVA GENERATOR | F9: Lagos | G9: Lagos Office | P9: MD RESIDENCE | R9: JUN
B10: 7 | D10: 6660001346 | E10: GML M SALEH 50KVA GENERATOR | F10: Port Harcourt | G10: GML Residence | P10: LAGOS OFFICE | R10: JUL
B11: 8 | D11: 6660000652 | E11: GML PERKINS 50KVA GENERATOR | F11: Port Harcourt | G11: GML Residence | P11: WOJI | R11: AUG
B12: 9 | D12: 6660001819 | E12: PHC OFFICE MIKANO 200KVA GENERATOR | F12: Port Harcourt | G12: Port Harcourt Office | P12: LAGOS GUEST HOUSE | R12: SEP
B13: 10 | D13: 6660002108 | E13: LAGOS OFFICE CUMMINS 135KVA GENERATOR | F13: Lagos | G13: Lagos Office | R13: OCT
B14: 11 | D14: 6660002135 | E14: PHC OFFICE CAT 350KVA GENERATOR | F14: Port Harcourt | G14: Port Harcourt Office | R14: NOV
B15: 12 | D15: 6660002687 | E15: AK LAGOS CAT 100KVA GENERATOR | F15: Lagos | G15: AK Residence | R15: DEC
B16: 13 | D16: 6660003092 | E16: DGS MIKANO 50KVA GENERATOR | F16: Port Harcourt | G16: DGS Residence
B17: 14 | D17: 6660003093 | E17: CHAIRMAN'S MIKANO 50KVA GENERATOR | F17: Uyo | G17: Chairman's Residence
B18: 15 | D18: 6660003107 | E18: BONNY PERKINS 60KVA GENERATOR | F18: Bonny | G18: Bonny Desicon Guest House
B19: 16 | D19: 6660003188 | E19: DR CUMMINS 275KVA GENERATOR | F19: Port Harcourt | G19: Desicon Guest House
B20: 17 | D20: 6660003189 | E20: PHC OFFICE CUMMINS 275KVA GENERATOR | F20: Port Harcourt | G20: Port Harcourt Office
B21: 18 | D21: 6660003658 | E21: AK UYO MARAPCO 100KVA GENERATOR | F21: Uyo | G21: AK Residence
B22: 19 | D22: Chairman | E22: CHAIRMAN'S PERKINS 30KVA GENERATOR | F22: Uyo | G22: Chairman's Residence
B23: 20 | D23: CHRM47 | E23: CHAIRMAN'S PERKINS 47KVA GENERATOR | F23: Uyo | G23: Chairman's Residence
B24: 21 | D24: CHRM40 | E24: CHAIRMAN'S PERKINS 40KVA GENERATOR | F24: Uyo - Village | G24: Chairman's Residence
B25: 22 | D25: MDYO100 | E25: AK UYO PERKINS 100KVA GENERATOR | F25: Uyo | G25: AK Residence
B26: 23 | D26: MDYO65 | E26: AK UYO PERKINS 65KVA GENERATOR | F26: Uyo | G26: AK Residence
B27: 23 | D27: MDLAG20 | E27: AK LAGOS 20KVA GENERATOR | F27: Lagos | G27: AK Residence
B28: 24 | D28: 6660024031 | E28: DR FG WILSON 150KVA GENERATOR | F28: Port Harcourt | G28: Desicon Guest House

Sheet Data_Analysis
C1: OVERALL MAINTENANCE COST - | F1: =$B$7+$K$26+$Y$7 -> 1686262.9
B3: EQUIPMENT DATA | K3: VEHICLE DATA | Y3: FACILITY DATA
A7: TOTAL COST | B7: =GETPIVOTDATA("SPARES COST",$A$8) -> 1686262.9 | J7: TOTAL COST | K7: =GETPIVOTDATA("SPARES COST (NGN)",$J$8) -> 0 | X7: TOTAL COST | Y7: =GETPIVOTDATA("SPARES COST (NGN)",$X$8) -> 0
A8: END USER | B8: MAINTENANCE COST | J8: LOCATION | K8: MAINTENANCE COST | X8: END USER | Y8: MAINTENANCE COST
A9: DR | B9: 134577 | E9: DR | F9: =GETPIVOTDATA("SPARES COST",$A$8,"LOCATION","DR") -> 134577 | G9: =F9/($F$9+$F$10) -> 0.07980784 | J9: Grand Total | N9: Port Harcourt | O9: =GETPIVOTDATA("SPARES COST (NGN)",$J$8,"REPAIR / MAINTENANCE LOCATION","Port Harcourt") -> #REF! | P9: =O9/($O$9+$O$10) -> #REF! | X9: (blank) | AB9: DR | AC9: =GETPIVOTDATA("SPARES COST (NGN)",$X$8,"LOCATION","DR") -> #REF! | AD9: =AC9/($AC$9+$AC$10) -> #REF!
A10: WOJI | E10: OTHER LOCATIONS | F10: =$B$7-F9 -> 1551685.9 | G10: =F10/($F$9+$F$10) -> 0.92019216 | N10: OTHER LOCATIONS | O10: =$K$7-O9 -> #REF! | P10: =O10/($O$9+$O$10) -> #REF! | X10: Grand Total | AB10: OTHERS | AC10: =$Y$7-AC9 -> #REF! | AD10: =AC10/($AC$9+$AC$10) -> #REF!
A11: PHC OFFICE | B11: 782520
A12: DGS | B12: 140195.9 | E12: WOJI | F12: =GETPIVOTDATA("SPARES COST",$A$8,"LOCATION","Woji") -> 0 | G12: =F12/($F$12+$F$13) -> 0 | N12: Lagos | O12: =GETPIVOTDATA("SPARES COST (NGN)",$J$8,"REPAIR / MAINTENANCE LOCATION","Lagos") -> #REF! | P12: =O12/($O$12+$O$13) -> #REF! | AB12: GML | AC12: =GETPIVOTDATA("SPARES COST (NGN)",$X$8,"LOCATION","GML") -> #REF! | AD12: =AC12/($AC$12+$AC$13) -> #REF!
A13: (blank) | B13: 628970 | E13: OTHER LOCATIONS | F13: =$B$7-F12 -> 1686262.9 | G13: =F13/($F$12+$F$13) -> 1 | N13: OTHER LOCATIONS | O13: =$K$7-O12 -> #REF! | P13: =O13/($O$12+$O$13) -> #REF! | AB13: OTHERS | AC13: =$Y$7-AC12 -> #REF! | AD13: =AC13/($AC$12+$AC$13) -> #REF!
A14: GML
A15: Grand Total | B15: 1686262.9 | E15: LAGOS OFFICE | F15: =GETPIVOTDATA("SPARES COST",$A$8,"LOCATION","LAGOS OFFICE") -> #REF! | G15: =F15/($F$15+$F$16) -> #REF! | N15: Abuja | O15: =GETPIVOTDATA("SPARES COST (NGN)",$J$8,"REPAIR / MAINTENANCE LOCATION","Abuja") -> #REF! | P15: =O15/($O$15+$O$16) -> #REF! | AB15: PHC OFFICE | AC15: =GETPIVOTDATA("SPARES COST (NGN)",$X$8,"LOCATION","PHC OFFICE") -> #REF! | AD15: =AC15/($AC$15+$AC$16) -> #REF!
E16: OTHER LOCATIONS | F16: =$B$7-F15 -> #REF! | G16: =F16/($F$15+$F$16) -> #REF! | N16: OTHER LOCATIONS | O16: =$K$7-O15 -> #REF! | P16: =O16/($O$15+$O$16) -> #REF! | AB16: OTHERS | AC16: =$Y$7-AC15 -> #REF! | AD16: =AC16/($AC$15+$AC$16) -> #REF!
E18: TOMY | F18: =GETPIVOTDATA("SPARES COST",$A$8,"LOCATION","TOMY") -> #REF! | G18: =F18/($F$18+$F$19) -> #REF! | N18: Uyo | O18: =GETPIVOTDATA("SPARES COST (NGN)",$J$8,"REPAIR / MAINTENANCE LOCATION","Uyo") -> #REF! | P18: =O18/($O$15+$O$16) -> #REF! | AB18: LAGOS OFFICE | AC18: =GETPIVOTDATA("SPARES COST (NGN)",$X$8,"LOCATION","LAGOS OFFICE") -> #REF! | AD18: =AC18/($AC$18+$AC$19) -> #REF!
E19: OTHER LOCATIONS | F19: =$B$7-F18 -> #REF! | G19: =F19/($F$18+$F$19) -> #REF! | N19: OTHER LOCATIONS | O19: =$K$7-O18 -> #REF! | P19: =O19/($O$15+$O$16) -> #REF! | AB19: OTHERS | AC19: =$Y$7-AC18 -> #REF! | AD19: =AC19/($AC$18+$AC$19) -> #REF!
E21: PHC OFFICE | F21: =GETPIVOTDATA("SPARES COST",$A$8,"LOCATION","PHC OFFICE") -> 782520 | G21: =F21/($F$21+$F$22) -> 0.46405575 | AB21: TOMY RESIDENCE | AC21: =GETPIVOTDATA("SPARES COST (NGN)",$X$8,"LOCATION","TOMY RESIDENCE") -> #REF! | AD21: =AC21/($AC$21+$AC$22) -> #REF!
E22: OTHER LOCATIONS | F22: =$B$7-F21 -> 903742.9 | G22: =F22/($F$21+$F$22) -> 0.53594425 | AB22: OTHERS | AC22: =$Y$7-AC21 -> #REF! | AD22: =AC22/($AC$21+$AC$22) -> #REF!
E24: DGS | F24: =GETPIVOTDATA("SPARES COST",$A$8,"LOCATION","DGS") -> 140195.9 | G24: =F24/($F$24+$F$25) -> 0.083140001 | AB24: AK GUEST HOUSE, LAGOG | AC24: =GETPIVOTDATA("SPARES COST (NGN)",$X$8,"LOCATION","AK GUEST HOUSE, LAGOS") -> #REF! | AD24: =AC24/($AC$24+$AC$25) -> #REF!
E25: OTHER LOCATIONS | F25: =$B$7-F24 -> 1546067 | G25: =F25/($F$24+$F$25) -> 0.91686 | J25: VEHICLE MONTHLY MAINTENANCE COST | N25: VEHICLE MONTHLY PERCENTAGE DEVIATION | AB25: OTHERS | AC25: =$Y$7-AC24 -> #REF! | AD25: =AC25/($AC$24+$AC$25) -> #REF!
K26: =GETPIVOTDATA("SPARES COST (NGN)",$J$27) -> 0
E27: GML | F27: =GETPIVOTDATA("SPARES COST",$A$8,"LOCATION","GML") -> 0 | G27: =F27/($F$24+$F$25) -> 0 | J27: MONTH | K27: MAINTENANCE COST | N27: DEC, 2023 | O27: 5384269 | P27: Percentage Deviation | AB27: DGS | AC27: =GETPIVOTDATA("SPARES COST (NGN)",$X$8,"LOCATION","DGS") -> #REF! | AD27: =AC27/($AC$27+$AC$28) -> #REF!
E28: OTHER LOCATIONS | F28: =$B$7-F27 -> 1686262.9 | G28: =F28/($F$24+$F$25) -> 1 | J28: (blank) | N28: Jan | O28: =GETPIVOTDATA("SPARES COST (NGN)",$J$27,"MONTH",$N28) -> #REF! | P28: =O28/O27-1 -> #REF! | AB28: OTHERS | AC28: =$Y$7-AC27 -> #REF! | AD28: =AC28/($AC$27+$AC$28) -> #REF!
J29: Grand Total | N29: Feb | O29: =GETPIVOTDATA("SPARES COST (NGN)",$J$27,"MONTH",$N29) -> #REF! | P29: =O29/O28-1 -> #REF!
E30: CHAIRMAN, UYO | F30: =GETPIVOTDATA("SPARES COST",$A$8,"LOCATION","CHAIRMAN, UYO") -> #REF! | G30: =F30/($F$24+$F$25) -> #REF! | N30: Mar | O30: =GETPIVOTDATA("SPARES COST (NGN)",$J$27,"MONTH",$N30) -> #REF! | P30: =O30/O29-1 -> #REF! | AB30: LAGOS GUEST HOUSE | AC30: =GETPIVOTDATA("SPARES COST (NGN)",$X$8,"LOCATION","LAGOS GUEST HOUSE") -> #REF! | AD30: =AC30/($AC$30+$AC$31) -> #REF!
E31: OTHER LOCATIONS | F31: =$B$7-F30 -> #REF! | G31: =F31/($F$24+$F$25) -> #REF! | N31: Apr | O31: =GETPIVOTDATA("SPARES COST (NGN)",$J$27,"MONTH",$N31) -> #REF! | P31: =O31/O30-1 -> #REF! | AB31: OTHERS | AC31: =$Y$7-AC30 -> #REF! | AD31: =AC31/($AC$30+$AC$31) -> #REF!
N32: May | O32: =GETPIVOTDATA("SPARES COST (NGN)",$J$27,"MONTH",$N32) -> #REF! | P32: =O32/O31-1 -> #REF!
E33: AK, UYO | F33: =GETPIVOTDATA("SPARES COST",$A$8,"LOCATION","AK, UYO") -> #REF! | G33: =F33/($F$24+$F$25) -> #REF! | N33: Jun | O33: =GETPIVOTDATA("SPARES COST (NGN)",$J$27,"MONTH",$N33) -> #REF! | P33: =O33/O32-1 -> #REF! | AB33: WOJI | AC33: =GETPIVOTDATA("SPARES COST (NGN)",$X$8,"LOCATION","WOJI") -> #REF! | AD33: =AC33/($AC$33+$AC$34) -> #REF!
E34: OTHER LOCATIONS | F34: =$B$7-F33 -> #REF! | G34: =F34/($F$24+$F$25) -> #REF! | N34: Jul | O34: =GETPIVOTDATA("SPARES COST (NGN)",$J$27,"MONTH",$N34) -> #REF! | P34: =O34/O33-1 -> #REF! | AB34: OTHERS | AC34: =$Y$7-AC33 -> #REF! | AD34: =AC34/($AC$33+$AC$34) -> #REF!
N35: Aug | O35: =GETPIVOTDATA("SPARES COST (NGN)",$J$27,"MONTH",$N35) -> #REF! | P35: =O35/O34-1 -> #REF!
N36: Sep | O36: =GETPIVOTDATA("SPARES COST (NGN)",$J$27,"MONTH",$N36) -> #REF! | P36: =O36/O35-1 -> #REF! | AB36: AK, LAGOS | AC36: =GETPIVOTDATA("SPARES COST (NGN)",$X$8,"LOCATION","AK, LAGOS") -> #REF! | AD36: =AC36/($AC$36+$AC$37) -> #REF!
N37: Oct | O37: =GETPIVOTDATA("SPARES COST (NGN)",$J$27,"MONTH",$N37) -> #REF! | P37: =O37/O36-1 -> #REF! | AB37: OTHERS | AC37: =$Y$7-AC36 -> #REF! | AD37: =AC37/($AC$36+$AC$37) -> #REF!
N38: Nov | O38: =GETPIVOTDATA("SPARES COST (NGN)",$J$27,"MONTH",$N38) -> #REF! | P38: =O38/O37-1 -> #REF!
AB39: AK, UYO | AC39: =GETPIVOTDATA("SPARES COST (NGN)",$X$8,"LOCATION","AK, UYO") -> #REF! | AD39: =AC39/($AC$36+$AC$37) -> #REF!
AB40: OTHERS | AC40: =$Y$7-AC39 -> #REF! | AD40: =AC40/($AC$36+$AC$37) -> #REF!
AB42: CHAIRMAN, UYO | AC42: =GETPIVOTDATA("SPARES COST (NGN)",$X$8,"LOCATION","CHAIRMAN UYO") -> #REF! | AD42: =AC42/($AC$36+$AC$37) -> #REF!
AB43: OTHERS | AC43: =$Y$7-AC42 -> #REF! | AD43: =AC43/($AC$36+$AC$37) -> #REF!
A47: MONTHLY EQUIPMENT MAINTENANCE COST
E48: MONTHLY EQUIPMENT PERCENTAGE DEVIATION | X48: FACILITY MONTHLY MAINTENANCE COST | AB48: FACILITY MONTHLY PERCENTAGE DEVIATION
A49: MONTH | B49: MAINTENANCE COST
A50: Jan | B50: 1300707 | E50: 2023 Dec | F50: 532114.25 | G50: Percentage Deviation | K50: =GETPIVOTDATA("SPARES COST (NGN)",$J$51) -> 0 | X50: MONTHS | Y50: MAINTENANCE COST | AB50: DEC. 2023 | AC50: 532114.25
A51: Feb | B51: 206555.9 | E51: Jan | F51: =GETPIVOTDATA("SPARES COST",$A$49,"MONTH",$E51) -> 1300707 | G51: =F51/F50-1 -> 1.444413 | J51: VEHICLE DESCRIPTION | K51: MAINTENANCE COST | X51: (blank) | AB51: Jan | AC51: =GETPIVOTDATA("SPARES COST (NGN)",$X$50,"MONTH",$AB51) -> #REF! | AD51: =AC51/AC50-1 -> #REF!
...

Sheet DashBoard
M92: MONTH | N92: MAINTENANCE COST | P92: =Data_Analysis!T52 -> #NUM! | S92: =Data_Analysis!U52 -> #NUM! | T92: =INDEX(Vehicle[REPAIR / MAINTENANCE LOCATION],MATCH(DashBoard!P92,Vehicle[VEHICLE REG NO.],0)) -> #NUM!
M93: (blank) | P93: =Data_Analysis!T53 -> #NUM! | S93: =Data_Analysis!U53 -> #NUM! | T93: =INDEX(Vehicle[REPAIR / MAINTENANCE LOCATION],MATCH(DashBoard!P93,Vehicle[VEHICLE REG NO.],0)) -> #NUM!
M94: Grand Total | P94: =Data_Analysis!T54 -> #NUM! | S94: =Data_Analysis!U54 -> #NUM! | T94: =INDEX(Vehicle[REPAIR / MAINTENANCE LOCATION],MATCH(DashBoard!P94,Vehicle[VEHICLE REG NO.],0)) -> #NUM!
P95: =Data_Analysis!T55 -> #NUM! | S95: =Data_Analysis!U55 -> #NUM! | T95: =INDEX(Vehicle[REPAIR / MAINTENANCE LOCATION],MATCH(DashBoard!P95,Vehicle[VEHICLE REG NO.],0)) -> #NUM!
P96: =Data_Analysis!T56 -> #NUM! | S96: =Data_Analysis!U56 -> #NUM! | T96: =INDEX(Vehicle[REPAIR / MAINTENANCE LOCATION],MATCH(DashBoard!P96,Vehicle[VEHICLE REG NO.],0)) -> #NUM!
M148: MONTH | N148: MAINTENANCE COST | P148: =Data_Analysis!G69 -> Grand Total | S148: =Data_Analysis!H69 -> 1686262.9 | T148: =INDEX(Equipment[END USER],MATCH(DashBoard!P148,Equipment[ASSET DESCRIPTION],0)) -> #N/A
M149: Jan | N149: 1300707 | P149: =Data_Analysis!G70 -> PHC OFFICE CAT 350KVA GENERATOR | S149: =Data_Analysis!H70 -> 782520 | T149: =INDEX(Equipment[END USER],MATCH(DashBoard!P149,Equipment[ASSET DESCRIPTION],0)) -> OFFICE
M150: Feb | N150: 206555.9 | P150: =Data_Analysis!G71 -> AK UYO PERKINS 100KVA GENERATOR | S150: =Data_Analysis!H71 -> 302488 | T150: =INDEX(Equipment[END USER],MATCH(DashBoard!P150,Equipment[ASSET DESCRIPTION],0)) -> MD
M151: Mar | N151: 162000 | P151: =Data_Analysis!G72 -> CHAIRMAN'S MIKANO 50KVA GENERATOR | S151: =Data_Analysis!H72 -> 174000 | T151: =INDEX(Equipment[END USER],MATCH(DashBoard!P151,Equipment[ASSET DESCRIPTION],0)) -> Chairman
M152: Apr | P152: =Data_Analysis!G73 -> DGS MIKANO 50KVA GENERATOR | S152: =Data_Analysis!H73 -> 157195.9 | T152: =INDEX(Equipment[END USER],MATCH(DashBoard!P152,Equipment[ASSET DESCRIPTION],0)) -> DGS
M153: May | N153: 17000
M154: (blank)
M155: Grand Total | N155: 1686262.9
M197: MONTH | N197: MAINTENANCE COST | P197: =Data_Analysis!AC73 -> #NUM! | R197: =Data_Analysis!AD73 -> #NUM! | S197: =INDEX(Facility[END USER],MATCH(P197,Facility[LOCATION],0)) -> #NUM!
M198: (blank) | P198: =Data_Analysis!AC74 -> #NUM! | R198: =Data_Analysis!AD74 -> #NUM! | S198: =INDEX(Facility[END USER],MATCH(P198,Facility[LOCATION],0)) -> #NUM!
M199: Grand Total | P199: =Data_Analysis!AC75 -> #NUM! | R199: =Data_Analysis!AD75 -> #NUM! | S199: =INDEX(Facility[END USER],MATCH(P199,Facility[LOCATION],0)) -> #NUM!
P200: =Data_Analysis!AC76 -> #NUM! | R200: =Data_Analysis!AD76 -> #NUM! | S200: =INDEX(Facility[END USER],MATCH(P200,Facility[LOCATION],0)) -> #NUM!
P201: =Data_Analysis!AC77 -> #NUM! | R201: =Data_Analysis!AD77 -> #NUM! | S201: =INDEX(Facility[END USER],MATCH(P201,Facility[LOCATION],0)) -> #NUM!
